<?xml version="1.0" encoding="utf-8"?>
<!-- This URDF was automatically created by SolidWorks to URDF Exporter! Originally created by Stephen Brawner (brawner@gmail.com) 
     Commit Version: 1.6.0-4-g7f85cfe  Build Version: 1.6.7995.38578
     For more information, please see http://wiki.ros.org/sw_urdf_exporter -->
<robot
  name="Robot_URDF_Visuals">
  <link
    name="Base_Link">
    <inertial>
      <origin
        xyz="-0.023518 -0.010863 0.071827"
        rpy="0 0 0" />
      <mass
        value="233.41" />
      <inertia
        ixx="10.744"
        ixy="0.13376"
        ixz="0.54602"
        iyy="10.299"
        iyz="0.28982"
        izz="11.726" />
    </inertial>
    <visual>
      <origin
        xyz="0 0 0"
        rpy="0 0 0" />
      <geometry>
        <mesh
          filename="package://Robot_URDF_Visuals/meshes/Base_Link.STL" />
      </geometry>
      <material
        name="">
        <color
          rgba="0.235 0.235 0.235 1" />
      </material>
    </visual>
    <collision>
      <origin
        xyz="0 0 0"
        rpy="0 0 0" />
      <geometry>
        <mesh
          filename="package://Robot_URDF_Visuals/meshes/Base_Link_Collision.STL" />
      </geometry>
    </collision>
  </link>
  <link
    name="Link_1">
    <inertial>
      <origin
        xyz="-4.4073E-18 1.5659E-19 0.027848"
        rpy="0 0 0" />
      <mass
        value="0.46369" />
      <inertia
        ixx="0.00017765"
        ixy="1.4414E-21"
        ixz="6.4285E-21"
        iyy="0.00016376"
        iyz="-2.9857E-20"
        izz="7.9649E-05" />
    </inertial>
    <visual>
      <origin
        xyz="0 0 0"
        rpy="0 0 0" />
      <geometry>
        <mesh
          filename="package://Robot_URDF_Visuals/meshes/Link_1.STL" />
      </geometry>
      <material
        name="">
        <color
          rgba="0.51 0.16 0.16 1" />
      </material>
    </visual>
    <collision>
      <origin
        xyz="0 0 0"
        rpy="0 0 0" />
      <geometry>
        <mesh
          filename="package://Robot_URDF_Visuals/meshes/Link_1_Collision.STL" />
      </geometry>
    </collision>
  </link>
  <joint
    name="Joint1"
    type="revolute">
    <origin
      xyz="0 0 0.09"
      rpy="0 0 0" />
    <parent
      link="Base_Link" />
    <child
      link="Link_1" />
    <axis
      xyz="0 0 -1" />
    <limit
      lower="-1.57"
      upper="1.57"
      effort="10"
      velocity="100" />
  </joint>
  <link
    name="Link_2">
    <inertial>
      <origin
        xyz="-0.06757 -0.0225 0"
        rpy="0 0 0" />
      <mass
        value="0.11993" />
      <inertia
        ixx="5.3919E-05"
        ixy="2.9147E-20"
        ixz="1.5432E-20"
        iyy="0.00022432"
        iyz="-1.7123E-21"
        izz="0.00026271" />
    </inertial>
    <visual>
      <origin
        xyz="0 0 0"
        rpy="0 0 0" />
      <geometry>
        <mesh
          filename="package://Robot_URDF_Visuals/meshes/Link_2.STL" />
      </geometry>
      <material
        name="">
        <color
          rgba="0.682 0.471 0.255 1" />
      </material>
    </visual>
    <collision>
      <origin
        xyz="0 0 0"
        rpy="0 0 0" />
      <geometry>
        <mesh
          filename="package://Robot_URDF_Visuals/meshes/Link_2_Collision.STL" />
      </geometry>
    </collision>
  </link>
  <joint
    name="Joint2"
    type="revolute">
    <origin
      xyz="0 0.0225 0.045"
      rpy="0 0 0" />
    <parent
      link="Link_1" />
    <child
      link="Link_2" />
    <axis
      xyz="-3.1128E-05 -1 0" />
    <limit
      lower="-1.57"
      upper="1.57"
      effort="10"
      velocity="100" />
  </joint>
  <link
    name="Link_3">
    <inertial>
      <origin
        xyz="-0.07128 -0.0275 2.7756E-17"
        rpy="0 0 0" />
      <mass
        value="0.12851" />
      <inertia
        ixx="8.1361E-05"
        ixy="6.4472E-20"
        ixz="-1.9113E-20"
        iyy="0.00023943"
        iyz="4.5184E-20"
        izz="0.00030386" />
    </inertial>
    <visual>
      <origin
        xyz="0 0 0"
        rpy="0 0 0" />
      <geometry>
        <mesh
          filename="package://Robot_URDF_Visuals/meshes/Link_3.STL" />
      </geometry>
      <material
        name="">
        <color
          rgba="0.824 0.765 0.353 1" />
      </material>
    </visual>
    <collision>
      <origin
        xyz="0 0 0"
        rpy="0 0 0" />
      <geometry>
        <mesh
          filename="package://Robot_URDF_Visuals/meshes/Link_3_Collision.STL" />
      </geometry>
    </collision>
  </link>
  <joint
    name="Joint3"
    type="revolute">
    <origin
      xyz="-0.107 0.005 0"
      rpy="0 0 0" />
    <parent
      link="Link_2" />
    <child
      link="Link_3" />
    <axis
      xyz="-3.1128E-05 -1 0" />
    <limit
      lower="-1.57"
      upper="1.57"
      effort="10"
      velocity="100" />
  </joint>
  <link
    name="Link_4">
    <inertial>
      <origin
        xyz="-0.045271 -0.035 5.5511E-17"
        rpy="0 0 0" />
      <mass
        value="0.14501" />
      <inertia
        ixx="0.00013446"
        ixy="-2.5635E-20"
        ixz="1.897E-20"
        iyy="0.00012072"
        iyz="-3.1903E-21"
        izz="0.00022946" />
    </inertial>
    <visual>
      <origin
        xyz="0 0 0"
        rpy="0 0 0" />
      <geometry>
        <mesh
          filename="package://Robot_URDF_Visuals/meshes/Link_4.STL" />
      </geometry>
      <material
        name="">
        <color
          rgba="0.431 0.784 0.824 1" />
      </material>
    </visual>
    <collision>
      <origin
        xyz="0 0 0"
        rpy="0 0 0" />
      <geometry>
        <mesh
          filename="package://Robot_URDF_Visuals/meshes/Link_4_Collision.STL" />
      </geometry>
    </collision>
  </link>
  <joint
    name="Joint4"
    type="revolute">
    <origin
      xyz="-0.107 0.0075 0"
      rpy="0 0 0" />
    <parent
      link="Link_3" />
    <child
      link="Link_4" />
    <axis
      xyz="3.1128E-05 1 0" />
    <limit
      lower="-1.57"
      upper="1.57"
      effort="10"
      velocity="100" />
  </joint>
  <link
    name="End_Effector_1">
    <inertial>
      <origin
        xyz="-0.0018349 0.0057553 -1.3167E-06"
        rpy="0 0 0" />
      <mass
        value="0.021787" />
      <inertia
        ixx="3.9936E-06"
        ixy="-8.6187E-07"
        ixz="5.2637E-11"
        iyy="5.8402E-06"
        iyz="-1.651E-10"
        izz="3.6098E-06" />
    </inertial>
    <visual>
      <origin
        xyz="0 0 0"
        rpy="0 0 0" />
      <geometry>
        <mesh
          filename="package://Robot_URDF_Visuals/meshes/End_Effector.STL" />
      </geometry>
      <material
        name="">
        <color
          rgba="0.863 0.118 0.784 1" />
      </material>
    </visual>
    <collision>
      <origin
        xyz="0 0 0"
        rpy="0 0 0" />
      <geometry>
        <mesh
          filename="package://Robot_URDF_Visuals/meshes/End_Effector_Collision.STL" />
      </geometry>
    </collision>
  </link>
</robot>