<?xml version="1.0" encoding="utf-8"?>
<!-- This URDF was automatically created by SolidWorks to URDF Exporter! Originally created by Stephen Brawner (brawner@gmail.com) 
     Commit Version: 1.6.0-4-g7f85cfe  Build Version: 1.6.7995.38578
     For more information, please see http://wiki.ros.org/sw_urdf_exporter -->
<robot
  name="Robot_URDF_Collisions">
  <link
    name="Base_Link">
    <inertial>
      <origin
        xyz="-0.020496 -1.1734E-17 0.041301"
        rpy="0 0 0" />
      <mass
        value="1.5719" />
      <inertia
        ixx="0.0036754"
        ixy="3.839E-19"
        ixz="-0.00037791"
        iyy="0.0034107"
        iyz="3.9689E-20"
        izz="0.0049558" />
    </inertial>
    <visual>
      <origin
        xyz="0 0 0"
        rpy="0 0 0" />
      <geometry>
        <mesh
          filename="package://Robot_URDF_Collisions/meshes/Base_Link.STL" />
      </geometry>
      <material
        name="">
        <color
          rgba="0.76078 0.4 0.18039 0.3" />
      </material>
    </visual>
    <collision>
      <origin
        xyz="0 0 0"
        rpy="0 0 0" />
      <geometry>
        <mesh
          filename="package://Robot_URDF_Collisions/meshes/Base_Link.STL" />
      </geometry>
    </collision>
  </link>
  <link
    name="Link_1">
    <inertial>
      <origin
        xyz="-3.8377E-18 7.2245E-19 0.028951"
        rpy="0 0 0" />
      <mass
        value="0.11977" />
      <inertia
        ixx="5.4579E-05"
        ixy="1.935E-21"
        ixz="-6.7437E-21"
        iyy="5.6798E-05"
        iyz="-5.6362E-21"
        izz="4.0198E-05" />
    </inertial>
    <visual>
      <origin
        xyz="0 0 0"
        rpy="0 0 0" />
      <geometry>
        <mesh
          filename="package://Robot_URDF_Collisions/meshes/Link_1.STL" />
      </geometry>
      <material
        name="">
        <color
          rgba="0.76078 0.4 0.18039 0.3" />
      </material>
    </visual>
    <collision>
      <origin
        xyz="0 0 0"
        rpy="0 0 0" />
      <geometry>
        <mesh
          filename="package://Robot_URDF_Collisions/meshes/Link_1.STL" />
      </geometry>
    </collision>
  </link>
  <joint
    name="Joint1"
    type="revolute">
    <origin
      xyz="0 0 0.09"
      rpy="0 0 0" />
    <parent
      link="Base_Link" />
    <child
      link="Link_1" />
    <axis
      xyz="0 0 -1" />
    <limit
      lower="-1.57"
      upper="1.57"
      effort="10"
      velocity="100" />
  </joint>
  <link
    name="Link_2">
    <inertial>
      <origin
        xyz="-0.08404 -0.0225 0"
        rpy="0 0 0" />
      <mass
        value="0.035" />
      <inertia
        ixx="1.2637E-05"
        ixy="-8.2939E-20"
        ixz="-2.7589E-21"
        iyy="5.5313E-05"
        iyz="3.3902E-21"
        izz="6.4304E-05" />
    </inertial>
    <visual>
      <origin
        xyz="0 0 0"
        rpy="0 0 0" />
      <geometry>
        <mesh
          filename="package://Robot_URDF_Collisions/meshes/Link_2.STL" />
      </geometry>
      <material
        name="">
        <color
          rgba="0.79216 0.81961 0.93333 1" />
      </material>
    </visual>
    <collision>
      <origin
        xyz="0 0 0"
        rpy="0 0 0" />
      <geometry>
        <mesh
          filename="package://Robot_URDF_Collisions/meshes/Link_2.STL" />
      </geometry>
    </collision>
  </link>
  <joint
    name="Joint2"
    type="revolute">
    <origin
      xyz="0 0.0225 0.045"
      rpy="0 0 0" />
    <parent
      link="Link_1" />
    <child
      link="Link_2" />
    <axis
      xyz="-3.1128E-05 -1 0" />
    <limit
      lower="-1.57"
      upper="1.57"
      effort="10"
      velocity="100" />
  </joint>
  <link
    name="Link_3">
    <inertial>
      <origin
        xyz="-0.087452 -0.0275 0"
        rpy="0 0 0" />
      <mass
        value="0.040535" />
      <inertia
        ixx="1.9849E-05"
        ixy="-5.9591E-20"
        ixz="-6.3064E-21"
        iyy="5.8759E-05"
        iyz="1.6257E-20"
        izz="7.4385E-05" />
    </inertial>
    <visual>
      <origin
        xyz="0 0 0"
        rpy="0 0 0" />
      <geometry>
        <mesh
          filename="package://Robot_URDF_Collisions/meshes/Link_3.STL" />
      </geometry>
      <material
        name="">
        <color
          rgba="0.79216 0.81961 0.93333 1" />
      </material>
    </visual>
    <collision>
      <origin
        xyz="0 0 0"
        rpy="0 0 0" />
      <geometry>
        <mesh
          filename="package://Robot_URDF_Collisions/meshes/Link_3.STL" />
      </geometry>
    </collision>
  </link>
  <joint
    name="Joint3"
    type="revolute">
    <origin
      xyz="-0.107 0.005 0"
      rpy="0 0 0" />
    <parent
      link="Link_2" />
    <child
      link="Link_3" />
    <axis
      xyz="-3.1128E-05 -1 0" />
    <limit
      lower="-1.57"
      upper="1.57"
      effort="10"
      velocity="100" />
  </joint>
  <link
    name="Link_4">
    <inertial>
      <origin
        xyz="-0.0500827074831178 -0.035 5.55111512312578E-17"
        rpy="0 0 0" />
      <mass
        value="0.0428779936935492" />
      <inertia
        ixx="3.06585438473803E-05"
        ixy="-9.21724822912108E-21"
        ixz="6.60555312680715E-21"
        iyy="2.59772230030836E-05"
        iyz="2.70011205575488E-21"
        izz="5.10330423411734E-05" />
    </inertial>
    <visual>
      <origin
        xyz="0 0 0"
        rpy="0 0 0" />
      <geometry>
        <mesh
          filename="package://Robot_URDF_Collisions/meshes/Link_4.STL" />
      </geometry>
      <material
        name="">
        <color
          rgba="0.792156862745098 0.819607843137255 0.933333333333333 1" />
      </material>
    </visual>
    <collision>
      <origin
        xyz="0 0 0"
        rpy="0 0 0" />
      <geometry>
        <mesh
          filename="package://Robot_URDF_Collisions/meshes/Link_4.STL" />
      </geometry>
    </collision>
  </link>
  <joint
    name="Joint4"
    type="revolute">
    <origin
      xyz="-0.107 0.0075 0"
      rpy="0 0 0" />
    <parent
      link="Link_3" />
    <child
      link="Link_4" />
    <axis
      xyz="3.1128E-05 1 0" />
    <limit
      lower="-1.57"
      upper="1.57"
      effort="10"
      velocity="100" />
  </joint>
  <link
    name="End_Effector_1">
    <inertial>
      <origin
        xyz="-0.009521 0.01 0"
        rpy="0 0 0" />
      <mass
        value="0.03612" />
      <inertia
        ixx="6.8929E-06"
        ixy="6.4939E-22"
        ixz="-2.3542E-22"
        iyy="1.0381E-05"
        iyz="-4.0022E-22"
        izz="6.1434E-06" />
    </inertial>
    <visual>
      <origin
        xyz="0 0 0"
        rpy="0 0 0" />
      <geometry>
        <mesh
          filename="package://Robot_URDF_Collisions/meshes/End_Effector_1.STL" />
      </geometry>
      <material
        name="">
        <color
          rgba="0.76078 0.4 0.18039 0.3" />
      </material>
    </visual>
    <collision>
      <origin
        xyz="0 0 0"
        rpy="0 0 0" />
      <geometry>
        <mesh
          filename="package://Robot_URDF_Collisions/meshes/End_Effector_1.STL" />
      </geometry>
    </collision>
  </link>
  <joint
    name="Joint5_1"
    type="prismatic">
    <origin
      xyz="-0.079479008517633 -0.0195000000000002 0"
      rpy="0 0 0" />
    <parent
      link="Link_4" />
    <child
      link="End_Effector_1" />
    <axis
      xyz="0 -0.996384215288845 -0.0849617297565994" />
    <limit
      lower="-1.57"
      upper="1.57"
      effort="10"
      velocity="100" />
  </joint>
  <link
    name="End_Effector_2">
    <inertial>
      <origin
        xyz="-0.009521 -0.041 -2.7756E-17"
        rpy="0 0 0" />
      <mass
        value="0.03612" />
      <inertia
        ixx="6.8929E-06"
        ixy="2.2811E-22"
        ixz="7.5778E-22"
        iyy="1.0381E-05"
        iyz="-2.4862E-22"
        izz="6.1434E-06" />
    </inertial>
    <visual>
      <origin
        xyz="0 0 0"
        rpy="0 0 0" />
      <geometry>
        <mesh
          filename="package://Robot_URDF_Collisions/meshes/End_Effector_2.STL" />
      </geometry>
      <material
        name="">
        <color
          rgba="0.76078 0.4 0.18039 0.3" />
      </material>
    </visual>
    <collision>
      <origin
        xyz="0 0 0"
        rpy="0 0 0" />
      <geometry>
        <mesh
          filename="package://Robot_URDF_Collisions/meshes/End_Effector_2.STL" />
      </geometry>
    </collision>
  </link>
  <joint
    name="Joint5_2"
    type="prismatic">
    <origin
      xyz="-0.079479008517633 -0.0195000000000002 0"
      rpy="0 0 0" />
    <parent
      link="Link_4" />
    <child
      link="End_Effector_2" />
    <axis
      xyz="0 -0.996384215288845 -0.0849617297565994" />
    <limit
      lower="-1.57"
      upper="1.57"
      effort="10"
      velocity="100" />
  </joint>
</robot>